Workbook
Name Average_Unit_Cost: 'Report Summary'!#REF!
Name Count_of_Current_Inventory: 'Report Summary'!$H$5
Name Count_of_Product: 'Report Summary'!$C$5
Name Notification_Alert_Reorder: 'Report Summary'!$L$10:$M$25
Name Reorder_Product_Counts: 'Report Summary'!$L$5
Name Reorder_Products_Notification: 'Report Summary'!$L$9
Name Slicer_Category: #N/A
Name Slicer_Category1: #N/A
Name Slicer_Ware_House_No.: #N/A
Name Sum_of_stock_Quantity: 'Report Summary'!#REF!
Name Sum_of_Total_Value: 'Report Summary'!$E$5

Sheet DashBoard
C12: =IF(C14="","✅ No Reorder Needed","⚠️ Attention Reorder Needed") -> ⚠️ Attention Reorder Needed
C14: {=IF(Notification_Alert_Reorder="","",Notification_Alert_Reorder)} -> ASW-038 | D14: 1
C15: ASW-040 | D15: 2
C16: ASW-036 | D16: 3
C17: ASW-018 | D17: 4
C18: ASW-001 | D18: 6
C19: ASW-029 | D19: 7
C20: ASW-005 | D20: 9
C21: ASW-012 | D21: 10
C22: ASW-035 | D22: 10
C23: ASW-037 | D23: 10
C24: ASW-006 | D24: 10
C25: ASW-028 | D25: 10
C26: ASW-031 | D26: 12
... C29: ASW-002 | D29: 12

Sheet Products
C3: HSN Code. | D3: Product | E3: Category | F3: Ware House No. | G3: Unit/Cost | H3: Selling Price | I3: Reorder Level
C4: ASW-001 | D4: Xiaomi Android TV | E4: Led TV | F4: WH-0041 | G4: 11000 | H4: 35000 | I4: 10
C5: ASW-002 | D5: iPhone 15 | E5: Mobile Phone | F5: WH-0041 | G5: 40000 | H5: 120000 | I5: 12
C6: ASW-003 | D6: Samsung Galaxy S23 FE | E6: Mobile Phone | F6: WH-0041 | G6: 16000 | H6: 50000 | I6: 11
C7: ASW-004 | D7: HP Envy x360 | E7: Laptop | F7: WH-0041 | G7: 15000 | H7: 45000 | I7: 10
C8: ASW-005 | D8: One Plus 12 | E8: Mobile Phone | F8: WH-0042 | G8: 11000 | H8: 35000 | I8: 12
C9: ASW-006 | D9: Google Pixel 7a | E9: Mobile Phone | F9: WH-0042 | G9: 23000 | H9: 70000 | I9: 10
C10: ASW-007 | D10: Motorola Edge 40 | E10: Mobile Phone | F10: WH-0042 | G10: 10000 | H10: 30000 | I10: 11
C11: ASW-008 | D11: HP Pavilion 15 | E11: Laptop | F11: WH-0042 | G11: 16000 | H11: 50000 | I11: 12
C12: ASW-009 | D12: Google Pixel 8 Pro | E12: Mobile Phone | F12: WH-0042 | G12: 20000 | H12: 60000 | I12: 12
C13: ASW-010 | D13: iPad Mini | E13: Tablet | F13: WH-0041 | G13: 20000 | H13: 60000 | I13: 11
C14: ASW-011 | D14: HP spectre x360 | E14: Laptop | F14: WH-0041 | G14: 20000 | H14: 60000 | I14: 10
C15: ASW-012 | D15: HP Victer 14s | E15: Laptop | F15: WH-0042 | G15: 23000 | H15: 70000 | I15: 10
... C43: ASW-040 | D43: iPad 16 Pro Max | E43: Mobile Phone | F43: WH-0042 | G43: 35000 | H43: 110000 | I43: 10
K54: T051 | L54: 45901 | M54: P001 | N54: Store A | O54: -2 | P54: Sale
K55: T052 | L55: 45901 | M55: P004 | N55: Store B | O55: -5 | P55: Sale
K56: T053 | L56: 45901 | M56: P007 | N56: Store C | O56: 20 | P56: Receipt
K57: T056 | L57: 45902 | M57: P002 | N57: Store A | O57: 15 | P57: Receipt
K58: T054 | L58: 45902 | M58: P003 | N58: Store A | O58: -3 | P58: Sale
K59: T055 | L59: 45902 | M59: P010 | N59: Store B | O59: -2 | P59: Sale
K60: T058 | L60: 45903 | M60: P006 | N60: Store B | O60: -2 | P60: Sale
K61: T059 | L61: 45903 | M61: P009 | N61: Store A | O61: -1 | P61: Sale
K62: T057 | L62: 45903 | M62: P015 | N62: Store C | O62: -4 | P62: Sale
K63: T060 | L63: 45904 | M63: P012 | N63: Store B | O63: 10 | P63: Receipt
K64: T062 | L64: 45904 | M64: P017 | N64: Store A | O64: -3 | P64: Sale
K65: T061 | L65: 45904 | M65: P019 | N65: Store C | O65: -6 | P65: Sale
... K74: T071 | L74: 45910 | M74: P002 | N74: Store C | O74: 15 | P74: Receipt

Sheet Vendor Info
C3: HSN Code. | D3: Product | E3: Vendor Comp. | F3: Delivery Time(in days) | G3: Contact Name | H3: E-mail ID
C4: ASW-001 | D4: Xiaomi Android TV | E4: Iris Computers Ltd | F4: 3 | G4: Richie Alexander | H4: support@iriscomputersltd.in
C5: ASW-002 | D5: iPhone 15 | E5: Tech Distributers | F5: 2 | G5: Amit Khandal | H5: support@techdistributers.in
C6: ASW-003 | D6: Samsung Galaxy S23 FE | E6: Tech Distributers | F6: 7 | G6: Amit Khandal | H6: support@techdistributers.in
C7: ASW-004 | D7: HP Envy x360 | E7: Redington India Ltd | F7: 5 | G7: Dipti Sharma | H7: support@redingtonindialtd.in
C8: ASW-005 | D8: One Plus 12 | E8: Foreighn Tech Distributers | F8: 7 | G8: John Smith | H8: support@foreighntechdistributers.in
C9: ASW-006 | D9: Google Pixel 7a | E9: Redington India Ltd | F9: 6 | G9: Dipti Sharma | H9: support@redingtonindialtd.in
C10: ASW-007 | D10: Motorola Edge 40 | E10: Global Tech | F10: 4 | G10: Sam Hopper | H10: support@globaltech.in
C11: ASW-008 | D11: HP Pavilion 15 | E11: Savex Technologies | F11: 6 | G11: Ashok Ghalot | H11: support@savextechnologies.in
C12: ASW-009 | D12: Google Pixel 8 Pro | E12: Savex Technologies | F12: 4 | G12: Ashok Ghalot | H12: support@savextechnologies.in
C13: ASW-010 | D13: iPad Mini | E13: Global Tech | F13: 3 | G13: Sam Hopper | H13: support@globaltech.in
C14: ASW-011 | D14: HP spectre x360 | E14: Savex Technologies | F14: 6 | G14: Ashok Ghalot | H14: support@savextechnologies.in
C15: ASW-012 | D15: HP Victer 14s | E15: Tech Distro | F15: 7 | G15: Omkar Sharma | H15: support@techdistro.in
... C43: ASW-040 | D43: iPad 16 Pro Max | E43: Redington India Ltd | F43: 4 | G43: Dipti Sharma | H43: support@redingtonindialtd.in

Sheet Transaction
C3: TransID | D3: Date | E3: HSN-Code | F3: Product | G3: Ware House No. | H3: Quantity | I3: Type
C4: T001 | D4: 45900 | E4: ASW-001 | F4: =_xlfn.XLOOKUP(Transaction_Data[[#This Row],[HSN-Code]],Product_Data[HSN Code.],Product_Data[Product],"") -> Xiaomi Android TV | G4: {=_xlfn.XLOOKUP(E4,Product_Data[[#All],[HSN Code.]],Product_Data[[#All],[Ware House No.]])} -> WH-0041 | H4: 20 | I4: Opening Stock
C5: T002 | D5: 45900 | E5: ASW-002 | F5: =_xlfn.XLOOKUP(Transaction_Data[[#This Row],[HSN-Code]],Product_Data[HSN Code.],Product_Data[Product],"") -> iPhone 15 | G5: {=_xlfn.XLOOKUP(E5,Product_Data[[#All],[HSN Code.]],Product_Data[[#All],[Ware House No.]])} -> WH-0041 | H5: 15 | I5: Opening Stock
C6: T003 | D6: 45900 | E6: ASW-003 | F6: =_xlfn.XLOOKUP(Transaction_Data[[#This Row],[HSN-Code]],Product_Data[HSN Code.],Product_Data[Product],"") -> Samsung Galaxy S23 FE | G6: {=_xlfn.XLOOKUP(E6,Product_Data[[#All],[HSN Code.]],Product_Data[[#All],[Ware House No.]])} -> WH-0041 | H6: 20 | I6: Opening Stock
C7: T004 | D7: 45900 | E7: ASW-004 | F7: =_xlfn.XLOOKUP(Transaction_Data[[#This Row],[HSN-Code]],Product_Data[HSN Code.],Product_Data[Product],"") -> HP Envy x360 | G7: {=_xlfn.XLOOKUP(E7,Product_Data[[#All],[HSN Code.]],Product_Data[[#All],[Ware House No.]])} -> WH-0041 | H7: 20 | I7: Opening Stock
C8: T005 | D8: 45900 | E8: ASW-005 | F8: =_xlfn.XLOOKUP(Transaction_Data[[#This Row],[HSN-Code]],Product_Data[HSN Code.],Product_Data[Product],"") -> One Plus 12 | G8: {=_xlfn.XLOOKUP(E8,Product_Data[[#All],[HSN Code.]],Product_Data[[#All],[Ware House No.]])} -> WH-0042 | H8: 10 | I8: Opening Stock
C9: T006 | D9: 45900 | E9: ASW-006 | F9: =_xlfn.XLOOKUP(Transaction_Data[[#This Row],[HSN-Code]],Product_Data[HSN Code.],Product_Data[Product],"") -> Google Pixel 7a | G9: {=_xlfn.XLOOKUP(E9,Product_Data[[#All],[HSN Code.]],Product_Data[[#All],[Ware House No.]])} -> WH-0042 | H9: 10 | I9: Opening Stock
C10: T007 | D10: 45900 | E10: ASW-007 | F10: =_xlfn.XLOOKUP(Transaction_Data[[#This Row],[HSN-Code]],Product_Data[HSN Code.],Product_Data[Product],"") -> Motorola Edge 40 | G10: {=_xlfn.XLOOKUP(E10,Product_Data[[#All],[HSN Code.]],Product_Data[[#All],[Ware House No.]])} -> WH-0042 | H10: 20 | I10: Opening Stock
C11: T008 | D11: 45900 | E11: ASW-008 | F11: =_xlfn.XLOOKUP(Transaction_Data[[#This Row],[HSN-Code]],Product_Data[HSN Code.],Product_Data[Product],"") -> HP Pavilion 15 | G11: {=_xlfn.XLOOKUP(E11,Product_Data[[#All],[HSN Code.]],Product_Data[[#All],[Ware House No.]])} -> WH-0042 | H11: 20 | I11: Opening Stock
C12: T009 | D12: 45900 | E12: ASW-009 | F12: =_xlfn.XLOOKUP(Transaction_Data[[#This Row],[HSN-Code]],Product_Data[HSN Code.],Product_Data[Product],"") -> Google Pixel 8 Pro | G12: {=_xlfn.XLOOKUP(E12,Product_Data[[#All],[HSN Code.]],Product_Data[[#All],[Ware House No.]])} -> WH-0042 | H12: 15 | I12: Opening Stock
C13: T010 | D13: 45900 | E13: ASW-010 | F13: =_xlfn.XLOOKUP(Transaction_Data[[#This Row],[HSN-Code]],Product_Data[HSN Code.],Product_Data[Product],"") -> iPad Mini | G13: {=_xlfn.XLOOKUP(E13,Product_Data[[#All],[HSN Code.]],Product_Data[[#All],[Ware House No.]])} -> WH-0041 | H13: 15 | I13: Opening Stock
C14: T011 | D14: 45900 | E14: ASW-011 | F14: =_xlfn.XLOOKUP(Transaction_Data[[#This Row],[HSN-Code]],Product_Data[HSN Code.],Product_Data[Product],"") -> HP spectre x360 | G14: {=_xlfn.XLOOKUP(E14,Product_Data[[#All],[HSN Code.]],Product_Data[[#All],[Ware House No.]])} -> WH-0041 | H14: 15 | I14: Opening Stock
C15: T012 | D15: 45900 | E15: ASW-012 | F15: =_xlfn.XLOOKUP(Transaction_Data[[#This Row],[HSN-Code]],Product_Data[HSN Code.],Product_Data[Product],"") -> HP Victer 14s | G15: {=_xlfn.XLOOKUP(E15,Product_Data[[#All],[HSN Code.]],Product_Data[[#All],[Ware House No.]])} -> WH-0042 | H15: 10 | I15: Opening Stock
... C43: T040 | D43: 45917 | E43: ASW-040 | F43: =_xlfn.XLOOKUP(Transaction_Data[[#This Row],[HSN-Code]],Product_Data[HSN Code.],Product_Data[Product],"") -> iPad 16 Pro Max | G43: {=_xlfn.XLOOKUP(E43,Product_Data[[#All],[HSN Code.]],Product_Data[[#All],[Ware House No.]])} -> WH-0042 | H43: 5 | I43: Opening Stock
C44: T041 | D44: 45920 | E44: ASW-003 | F44: =_xlfn.XLOOKUP(Transaction_Data[[#This Row],[HSN-Code]],Product_Data[HSN Code.],Product_Data[Product],"") -> Samsung Galaxy S23 FE | G44: {=_xlfn.XLOOKUP(E44,Product_Data[[#All],[HSN Code.]],Product_Data[[#All],[Ware House No.]],"")} -> WH-0041 | H44: -5 | I44: =IF(H44="","",IF(H44>0,"Reciept","Sale")) -> Sale
C45: T042 | D45: 45921 | E45: ASW-005 | F45: =_xlfn.XLOOKUP(Transaction_Data[[#This Row],[HSN-Code]],Product_Data[HSN Code.],Product_Data[Product],"") -> One Plus 12 | G45: {=_xlfn.XLOOKUP(E45,Product_Data[[#All],[HSN Code.]],Product_Data[[#All],[Ware House No.]],"")} -> WH-0042 | H45: -6 | I45: =IF(H45="","",IF(H45>0,"Reciept","Sale")) -> Sale
C46: T043 | D46: 45922 | E46: ASW-007 | F46: =_xlfn.XLOOKUP(Transaction_Data[[#This Row],[HSN-Code]],Product_Data[HSN Code.],Product_Data[Product],"") -> Motorola Edge 40 | G46: {=_xlfn.XLOOKUP(E46,Product_Data[[#All],[HSN Code.]],Product_Data[[#All],[Ware House No.]],"")} -> WH-0042 | H46: -2 | I46: =IF(H46="","",IF(H46>0,"Reciept","Sale")) -> Sale
C47: T044 | D47: 45923 | E47: ASW-013 | F47: =_xlfn.XLOOKUP(Transaction_Data[[#This Row],[HSN-Code]],Product_Data[HSN Code.],Product_Data[Product],"") -> MacBook Pro M3 Max 16 | G47: {=_xlfn.XLOOKUP(E47,Product_Data[[#All],[HSN Code.]],Product_Data[[#All],[Ware House No.]],"")} -> WH-0041 | H47: -1 | I47: =IF(H47="","",IF(H47>0,"Reciept","Sale")) -> Sale
C48: T045 | D48: 45924 | E48: ASW-040 | F48: =_xlfn.XLOOKUP(Transaction_Data[[#This Row],[HSN-Code]],Product_Data[HSN Code.],Product_Data[Product],"") -> iPad 16 Pro Max | G48: {=_xlfn.XLOOKUP(E48,Product_Data[[#All],[HSN Code.]],Product_Data[[#All],[Ware House No.]],"")} -> WH-0042 | H48: -1 | I48: =IF(H48="","",IF(H48>0,"Reciept","Sale")) -> Sale
C49: T046 | D49: 45925 | E49: ASW-040 | F49: =_xlfn.XLOOKUP(Transaction_Data[[#This Row],[HSN-Code]],Product_Data[HSN Code.],Product_Data[Product],"") -> iPad 16 Pro Max | G49: {=_xlfn.XLOOKUP(E49,Product_Data[[#All],[HSN Code.]],Product_Data[[#All],[Ware House No.]],"")} -> WH-0042 | H49: -2 | I49: =IF(H49="","",IF(H49>0,"Reciept","Sale")) -> Sale
C50: T047 | D50: 45925 | E50: ASW-015 | F50: =_xlfn.XLOOKUP(Transaction_Data[[#This Row],[HSN-Code]],Product_Data[HSN Code.],Product_Data[Product],"") -> Asus Zenbook 14 | G50: {=_xlfn.XLOOKUP(E50,Product_Data[[#All],[HSN Code.]],Product_Data[[#All],[Ware House No.]],"")} -> WH-0042 | H50: -1 | I50: =IF(H50="","",IF(H50>0,"Reciept","Sale")) -> Sale
C51: T048 | D51: 45925 | E51: ASW-009 | F51: =_xlfn.XLOOKUP(Transaction_Data[[#This Row],[HSN-Code]],Product_Data[HSN Code.],Product_Data[Product],"") -> Google Pixel 8 Pro | G51: {=_xlfn.XLOOKUP(E51,Product_Data[[#All],[HSN Code.]],Product_Data[[#All],[Ware House No.]],"")} -> WH-0042 | H51: -1 | I51: =IF(H51="","",IF(H51>0,"Reciept","Sale")) -> Sale
C52: T049 | D52: 45929 | E52: ASW-034 | F52: =_xlfn.XLOOKUP(Transaction_Data[[#This Row],[HSN-Code]],Product_Data[HSN Code.],Product_Data[Product],"") -> iPad 9th Gen | G52: {=_xlfn.XLOOKUP(E52,Product_Data[[#All],[HSN Code.]],Product_Data[[#All],[Ware House No.]],"")} -> WH-0042 | H52: -1 | I52: =IF(H52="","",IF(H52>0,"Reciept","Sale")) -> Sale
C53: T050 | D53: 45932 | E53: ASW-035 | F53: =_xlfn.XLOOKUP(Transaction_Data[[#This Row],[HSN-Code]],Product_Data[HSN Code.],Product_Data[Product],"") -> Sony Bravia Smart 4K | G53: {=_xlfn.XLOOKUP(E53,Product_Data[[#All],[HSN Code.]],Product_Data[[#All],[Ware House No.]],"")} -> WH-0041 | H53: -3 | I53: =IF(H53="","",IF(H53>0,"Reciept","Sale")) -> Sale
C54: T051 | D54: 45940 | E54: ASW-014 | F54: =_xlfn.XLOOKUP(Transaction_Data[[#This Row],[HSN-Code]],Product_Data[HSN Code.],Product_Data[Product],"") -> iPad Pro 12 | G54: {=_xlfn.XLOOKUP(E54,Product_Data[[#All],[HSN Code.]],Product_Data[[#All],[Ware House No.]],"")} -> WH-0041 | H54: -3 | I54: =IF(H54="","",IF(H54>0,"Reciept","Sale")) -> Sale
C55: T052 | D55: 45945 | E55: ASW-029 | F55: =_xlfn.XLOOKUP(Transaction_Data[[#This Row],[HSN-Code]],Product_Data[HSN Code.],Product_Data[Product],"") -> Samsung Galaxy S24+ | G55: {=_xlfn.XLOOKUP(E55,Product_Data[[#All],[HSN Code.]],Product_Data[[#All],[Ware House No.]],"")} -> WH-0042 | H55: -3 | I55: =IF(H55="","",IF(H55>0,"Reciept","Sale")) -> Sale
... C78: T075 | D78: 46013 | E78: ASW-030 | F78: =_xlfn.XLOOKUP(Transaction_Data[[#This Row],[HSN-Code]],Product_Data[HSN Code.],Product_Data[Product],"") -> One Plus Ultra | G78: {=_xlfn.XLOOKUP(E78,Product_Data[[#All],[HSN Code.]],Product_Data[[#All],[Ware House No.]],"")} -> WH-0041 | H78: 9 | I78: =IF(H78="","",IF(H78>0,"Reciept","Sale")) -> Reciept
G79: {=_xlfn.XLOOKUP(E79,Product_Data[[#All],[HSN Code.]],Product_Data[[#All],[Ware House No.]],"")}
G80: {=_xlfn.XLOOKUP(E80,Product_Data[[#All],[HSN Code.]],Product_Data[[#All],[Ware House No.]],"")}
G81: {=_xlfn.XLOOKUP(E81,Product_Data[[#All],[HSN Code.]],Product_Data[[#All],[Ware House No.]],"")}
G82: {=_xlfn.XLOOKUP(E82,Product_Data[[#All],[HSN Code.]],Product_Data[[#All],[Ware House No.]],"")}
G83: {=_xlfn.XLOOKUP(E83,Product_Data[[#All],[HSN Code.]],Product_Data[[#All],[Ware House No.]],"")}
G84: {=_xlfn.XLOOKUP(E84,Product_Data[[#All],[HSN Code.]],Product_Data[[#All],[Ware House No.]],"")}
G85: {=_xlfn.XLOOKUP(E85,Product_Data[[#All],[HSN Code.]],Product_Data[[#All],[Ware House No.]],"")}
G86: {=_xlfn.XLOOKUP(E86,Product_Data[[#All],[HSN Code.]],Product_Data[[#All],[Ware House No.]],"")}
G87: {=_xlfn.XLOOKUP(E87,Product_Data[[#All],[HSN Code.]],Product_Data[[#All],[Ware House No.]],"")}
G88: {=_xlfn.XLOOKUP(E88,Product_Data[[#All],[HSN Code.]],Product_Data[[#All],[Ware House No.]],"")}
G89: {=_xlfn.XLOOKUP(E89,Product_Data[[#All],[HSN Code.]],Product_Data[[#All],[Ware House No.]],"")}
G90: {=_xlfn.XLOOKUP(E90,Product_Data[[#All],[HSN Code.]],Product_Data[[#All],[Ware House No.]],"")}
... G96: {=_xlfn.XLOOKUP(E96,Product_Data[[#All],[HSN Code.]],Product_Data[[#All],[Ware House No.]],"")}

Sheet Inventory
C3: HSN-Code | D3: Ware House No. | E3: Product | F3: Category | G3: Unit/Cost | H3: Selling Price | I3: Quantity in Stock | J3: Total Value | K3: Reorder Level | L3: Status
C4: ASW-001 | D4: =_xlfn.XLOOKUP(Inventory_Data[[#This Row],[HSN-Code]],Product_Data[HSN Code.],Product_Data[Ware House No.],"") -> WH-0041 | E4: =_xlfn.XLOOKUP(C4,Product_Data[HSN Code.],Product_Data[Product],"") -> Xiaomi Android TV | F4: =_xlfn.XLOOKUP(C4,Product_Data[HSN Code.],Product_Data[Category],"") -> Led TV | G4: =_xlfn.XLOOKUP(C4,Product_Data[HSN Code.],Product_Data[Unit/Cost],"") -> 11000 | H4: =_xlfn.XLOOKUP(C4,Product_Data[HSN Code.],Product_Data[Selling Price],"") -> 35000 | I4: =SUMIFS(Transaction_Data[Quantity],Transaction_Data[HSN-Code],Inventory_Data[[#This Row],[HSN-Code]],Transaction_Data[Ware House No.],Inventory_Data[[#This Row],[Ware House No.]]) -> 6 | J4: =Inventory_Data[[#This Row],[Quantity in Stock]]*Inventory_Data[[#This Row],[Unit/Cost]] -> 66000 | K4: =_xlfn.XLOOKUP(Inventory_Data[[#This Row],[HSN-Code]],Product_Data[HSN Code.],Product_Data[Reorder Level],"") -> 10 | L4: =IF(Inventory_Data[[#This Row],[Reorder Level]]>=Inventory_Data[[#This Row],[Quantity in Stock]],"Yes","No") -> Yes
C5: ASW-002 | D5: =_xlfn.XLOOKUP(Inventory_Data[[#This Row],[HSN-Code]],Product_Data[HSN Code.],Product_Data[Ware House No.],"") -> WH-0041 | E5: =_xlfn.XLOOKUP(C5,Product_Data[HSN Code.],Product_Data[Product],"") -> iPhone 15 | F5: =_xlfn.XLOOKUP(C5,Product_Data[HSN Code.],Product_Data[Category],"") -> Mobile Phone | G5: =_xlfn.XLOOKUP(C5,Product_Data[HSN Code.],Product_Data[Unit/Cost],"") -> 40000 | H5: =_xlfn.XLOOKUP(C5,Product_Data[HSN Code.],Product_Data[Selling Price],"") -> 120000 | I5: =SUMIFS(Transaction_Data[Quantity],Transaction_Data[HSN-Code],Inventory_Data[[#This Row],[HSN-Code]],Transaction_Data[Ware House No.],Inventory_Data[[#This Row],[Ware House No.]]) -> 12 | J5: =Inventory_Data[[#This Row],[Quantity in Stock]]*Inventory_Data[[#This Row],[Unit/Cost]] -> 480000 | K5: =_xlfn.XLOOKUP(Inventory_Data[[#This Row],[HSN-Code]],Product_Data[HSN Code.],Product_Data[Reorder Level],"") -> 12 | L5: =IF(Inventory_Data[[#This Row],[Reorder Level]]>=Inventory_Data[[#This Row],[Quantity in Stock]],"Yes","No") -> Yes
C6: ASW-003 | D6: =_xlfn.XLOOKUP(Inventory_Data[[#This Row],[HSN-Code]],Product_Data[HSN Code.],Product_Data[Ware House No.],"") -> WH-0041 | E6: =_xlfn.XLOOKUP(C6,Product_Data[HSN Code.],Product_Data[Product],"") -> Samsung Galaxy S23 FE | F6: =_xlfn.XLOOKUP(C6,Product_Data[HSN Code.],Product_Data[Category],"") -> Mobile Phone | G6: =_xlfn.XLOOKUP(C6,Product_Data[HSN Code.],Product_Data[Unit/Cost],"") -> 16000 | H6: =_xlfn.XLOOKUP(C6,Product_Data[HSN Code.],Product_Data[Selling Price],"") -> 50000 | I6: =SUMIFS(Transaction_Data[Quantity],Transaction_Data[HSN-Code],Inventory_Data[[#This Row],[HSN-Code]],Transaction_Data[Ware House No.],Inventory_Data[[#This Row],[Ware House No.]]) -> 15 | J6: =Inventory_Data[[#This Row],[Quantity in Stock]]*Inventory_Data[[#This Row],[Unit/Cost]] -> 240000 | K6: =_xlfn.XLOOKUP(Inventory_Data[[#This Row],[HSN-Code]],Product_Data[HSN Code.],Product_Data[Reorder Level],"") -> 11 | L6: =IF(Inventory_Data[[#This Row],[Reorder Level]]>=Inventory_Data[[#This Row],[Quantity in Stock]],"Yes","No") -> No
C7: ASW-004 | D7: =_xlfn.XLOOKUP(Inventory_Data[[#This Row],[HSN-Code]],Product_Data[HSN Code.],Product_Data[Ware House No.],"") -> WH-0041 | E7: =_xlfn.XLOOKUP(C7,Product_Data[HSN Code.],Product_Data[Product],"") -> HP Envy x360 | F7: =_xlfn.XLOOKUP(C7,Product_Data[HSN Code.],Product_Data[Category],"") -> Laptop | G7: =_xlfn.XLOOKUP(C7,Product_Data[HSN Code.],Product_Data[Unit/Cost],"") -> 15000 | H7: =_xlfn.XLOOKUP(C7,Product_Data[HSN Code.],Product_Data[Selling Price],"") -> 45000 | I7: =SUMIFS(Transaction_Data[Quantity],Transaction_Data[HSN-Code],Inventory_Data[[#This Row],[HSN-Code]],Transaction_Data[Ware House No.],Inventory_Data[[#This Row],[Ware House No.]]) -> 15 | J7: =Inventory_Data[[#This Row],[Quantity in Stock]]*Inventory_Data[[#This Row],[Unit/Cost]] -> 225000 | K7: =_xlfn.XLOOKUP(Inventory_Data[[#This Row],[HSN-Code]],Product_Data[HSN Code.],Product_Data[Reorder Level],"") -> 10 | L7: =IF(Inventory_Data[[#This Row],[Reorder Level]]>=Inventory_Data[[#This Row],[Quantity in Stock]],"Yes","No") -> No
C8: ASW-005 | D8: =_xlfn.XLOOKUP(Inventory_Data[[#This Row],[HSN-Code]],Product_Data[HSN Code.],Product_Data[Ware House No.],"") -> WH-0042 | E8: =_xlfn.XLOOKUP(C8,Product_Data[HSN Code.],Product_Data[Product],"") -> One Plus 12 | F8: =_xlfn.XLOOKUP(C8,Product_Data[HSN Code.],Product_Data[Category],"") -> Mobile Phone | G8: =_xlfn.XLOOKUP(C8,Product_Data[HSN Code.],Product_Data[Unit/Cost],"") -> 11000 | H8: =_xlfn.XLOOKUP(C8,Product_Data[HSN Code.],Product_Data[Selling Price],"") -> 35000 | I8: =SUMIFS(Transaction_Data[Quantity],Transaction_Data[HSN-Code],Inventory_Data[[#This Row],[HSN-Code]],Transaction_Data[Ware House No.],Inventory_Data[[#This Row],[Ware House No.]]) -> 9 | J8: =Inventory_Data[[#This Row],[Quantity in Stock]]*Inventory_Data[[#This Row],[Unit/Cost]] -> 99000 | K8: =_xlfn.XLOOKUP(Inventory_Data[[#This Row],[HSN-Code]],Product_Data[HSN Code.],Product_Data[Reorder Level],"") -> 12 | L8: =IF(Inventory_Data[[#This Row],[Reorder Level]]>=Inventory_Data[[#This Row],[Quantity in Stock]],"Yes","No") -> Yes
C9: ASW-006 | D9: =_xlfn.XLOOKUP(Inventory_Data[[#This Row],[HSN-Code]],Product_Data[HSN Code.],Product_Data[Ware House No.],"") -> WH-0042 | E9: =_xlfn.XLOOKUP(C9,Product_Data[HSN Code.],Product_Data[Product],"") -> Google Pixel 7a | F9: =_xlfn.XLOOKUP(C9,Product_Data[HSN Code.],Product_Data[Category],"") -> Mobile Phone | G9: =_xlfn.XLOOKUP(C9,Product_Data[HSN Code.],Product_Data[Unit/Cost],"") -> 23000 | H9: =_xlfn.XLOOKUP(C9,Product_Data[HSN Code.],Product_Data[Selling Price],"") -> 70000 | I9: =SUMIFS(Transaction_Data[Quantity],Transaction_Data[HSN-Code],Inventory_Data[[#This Row],[HSN-Code]],Transaction_Data[Ware House No.],Inventory_Data[[#This Row],[Ware House No.]]) -> 10 | J9: =Inventory_Data[[#This Row],[Quantity in Stock]]*Inventory_Data[[#This Row],[Unit/Cost]] -> 230000 | K9: =_xlfn.XLOOKUP(Inventory_Data[[#This Row],[HSN-Code]],Product_Data[HSN Code.],Product_Data[Reorder Level],"") -> 10 | L9: =IF(Inventory_Data[[#This Row],[Reorder Level]]>=Inventory_Data[[#This Row],[Quantity in Stock]],"Yes","No") -> Yes
C10: ASW-007 | D10: =_xlfn.XLOOKUP(Inventory_Data[[#This Row],[HSN-Code]],Product_Data[HSN Code.],Product_Data[Ware House No.],"") -> WH-0042 | E10: =_xlfn.XLOOKUP(C10,Product_Data[HSN Code.],Product_Data[Product],"") -> Motorola Edge 40 | F10: =_xlfn.XLOOKUP(C10,Product_Data[HSN Code.],Product_Data[Category],"") -> Mobile Phone | G10: =_xlfn.XLOOKUP(C10,Product_Data[HSN Code.],Product_Data[Unit/Cost],"") -> 10000 | H10: =_xlfn.XLOOKUP(C10,Product_Data[HSN Code.],Product_Data[Selling Price],"") -> 30000 | I10: =SUMIFS(Transaction_Data[Quantity],Transaction_Data[HSN-Code],Inventory_Data[[#This Row],[HSN-Code]],Transaction_Data[Ware House No.],Inventory_Data[[#This Row],[Ware House No.]]) -> 18 | J10: =Inventory_Data[[#This Row],[Quantity in Stock]]*Inventory_Data[[#This Row],[Unit/Cost]] -> 180000 | K10: =_xlfn.XLOOKUP(Inventory_Data[[#This Row],[HSN-Code]],Product_Data[HSN Code.],Product_Data[Reorder Level],"") -> 11 | L10: =IF(Inventory_Data[[#This Row],[Reorder Level]]>=Inventory_Data[[#This Row],[Quantity in Stock]],"Yes","No") -> No
C11: ASW-008 | D11: =_xlfn.XLOOKUP(Inventory_Data[[#This Row],[HSN-Code]],Product_Data[HSN Code.],Product_Data[Ware House No.],"") -> WH-0042 | E11: =_xlfn.XLOOKUP(C11,Product_Data[HSN Code.],Product_Data[Product],"") -> HP Pavilion 15 | F11: =_xlfn.XLOOKUP(C11,Product_Data[HSN Code.],Product_Data[Category],"") -> Laptop | G11: =_xlfn.XLOOKUP(C11,Product_Data[HSN Code.],Product_Data[Unit/Cost],"") -> 16000 | H11: =_xlfn.XLOOKUP(C11,Product_Data[HSN Code.],Product_Data[Selling Price],"") -> 50000 | I11: =SUMIFS(Transaction_Data[Quantity],Transaction_Data[HSN-Code],Inventory_Data[[#This Row],[HSN-Code]],Transaction_Data[Ware House No.],Inventory_Data[[#This Row],[Ware House No.]]) -> 20 | J11: =Inventory_Data[[#This Row],[Quantity in Stock]]*Inventory_Data[[#This Row],[Unit/Cost]] -> 320000 | K11: =_xlfn.XLOOKUP(Inventory_Data[[#This Row],[HSN-Code]],Product_Data[HSN Code.],Product_Data[Reorder Level],"") -> 12 | L11: =IF(Inventory_Data[[#This Row],[Reorder Level]]>=Inventory_Data[[#This Row],[Quantity in Stock]],"Yes","No") -> No
C12: ASW-009 | D12: =_xlfn.XLOOKUP(Inventory_Data[[#This Row],[HSN-Code]],Product_Data[HSN Code.],Product_Data[Ware House No.],"") -> WH-0042 | E12: =_xlfn.XLOOKUP(C12,Product_Data[HSN Code.],Product_Data[Product],"") -> Google Pixel 8 Pro | F12: =_xlfn.XLOOKUP(C12,Product_Data[HSN Code.],Product_Data[Category],"") -> Mobile Phone | G12: =_xlfn.XLOOKUP(C12,Product_Data[HSN Code.],Product_Data[Unit/Cost],"") -> 20000 | H12: =_xlfn.XLOOKUP(C12,Product_Data[HSN Code.],Product_Data[Selling Price],"") -> 60000 | I12: =SUMIFS(Transaction_Data[Quantity],Transaction_Data[HSN-Code],Inventory_Data[[#This Row],[HSN-Code]],Transaction_Data[Ware House No.],Inventory_Data[[#This Row],[Ware House No.]]) -> 14 | J12: =Inventory_Data[[#This Row],[Quantity in Stock]]*Inventory_Data[[#This Row],[Unit/Cost]] -> 280000 | K12: =_xlfn.XLOOKUP(Inventory_Data[[#This Row],[HSN-Code]],Product_Data[HSN Code.],Product_Data[Reorder Level],"") -> 12 | L12: =IF(Inventory_Data[[#This Row],[Reorder Level]]>=Inventory_Data[[#This Row],[Quantity in Stock]],"Yes","No") -> No
C13: ASW-010 | D13: =_xlfn.XLOOKUP(Inventory_Data[[#This Row],[HSN-Code]],Product_Data[HSN Code.],Product_Data[Ware House No.],"") -> WH-0041 | E13: =_xlfn.XLOOKUP(C13,Product_Data[HSN Code.],Product_Data[Product],"") -> iPad Mini | F13: =_xlfn.XLOOKUP(C13,Product_Data[HSN Code.],Product_Data[Category],"") -> Tablet | G13: =_xlfn.XLOOKUP(C13,Product_Data[HSN Code.],Product_Data[Unit/Cost],"") -> 20000 | H13: =_xlfn.XLOOKUP(C13,Product_Data[HSN Code.],Product_Data[Selling Price],"") -> 60000 | I13: =SUMIFS(Transaction_Data[Quantity],Transaction_Data[HSN-Code],Inventory_Data[[#This Row],[HSN-Code]],Transaction_Data[Ware House No.],Inventory_Data[[#This Row],[Ware House No.]]) -> 15 | J13: =Inventory_Data[[#This Row],[Quantity in Stock]]*Inventory_Data[[#This Row],[Unit/Cost]] -> 300000 | K13: =_xlfn.XLOOKUP(Inventory_Data[[#This Row],[HSN-Code]],Product_Data[HSN Code.],Product_Data[Reorder Level],"") -> 11 | L13: =IF(Inventory_Data[[#This Row],[Reorder Level]]>=Inventory_Data[[#This Row],[Quantity in Stock]],"Yes","No") -> No
C14: ASW-011 | D14: =_xlfn.XLOOKUP(Inventory_Data[[#This Row],[HSN-Code]],Product_Data[HSN Code.],Product_Data[Ware House No.],"") -> WH-0041 | E14: =_xlfn.XLOOKUP(C14,Product_Data[HSN Code.],Product_Data[Product],"") -> HP spectre x360 | F14: =_xlfn.XLOOKUP(C14,Product_Data[HSN Code.],Product_Data[Category],"") -> Laptop | G14: =_xlfn.XLOOKUP(C14,Product_Data[HSN Code.],Product_Data[Unit/Cost],"") -> 20000 | H14: =_xlfn.XLOOKUP(C14,Product_Data[HSN Code.],Product_Data[Selling Price],"") -> 60000 | I14: =SUMIFS(Transaction_Data[Quantity],Transaction_Data[HSN-Code],Inventory_Data[[#This Row],[HSN-Code]],Transaction_Data[Ware House No.],Inventory_Data[[#This Row],[Ware House No.]]) -> 15 | J14: =Inventory_Data[[#This Row],[Quantity in Stock]]*Inventory_Data[[#This Row],[Unit/Cost]] -> 300000 | K14: =_xlfn.XLOOKUP(Inventory_Data[[#This Row],[HSN-Code]],Product_Data[HSN Code.],Product_Data[Reorder Level],"") -> 10 | L14: =IF(Inventory_Data[[#This Row],[Reorder Level]]>=Inventory_Data[[#This Row],[Quantity in Stock]],"Yes","No") -> No
C15: ASW-012 | D15: =_xlfn.XLOOKUP(Inventory_Data[[#This Row],[HSN-Code]],Product_Data[HSN Code.],Product_Data[Ware House No.],"") -> WH-0042 | E15: =_xlfn.XLOOKUP(C15,Product_Data[HSN Code.],Product_Data[Product],"") -> HP Victer 14s | F15: =_xlfn.XLOOKUP(C15,Product_Data[HSN Code.],Product_Data[Category],"") -> Laptop | G15: =_xlfn.XLOOKUP(C15,Product_Data[HSN Code.],Product_Data[Unit/Cost],"") -> 23000 | H15: =_xlfn.XLOOKUP(C15,Product_Data[HSN Code.],Product_Data[Selling Price],"") -> 70000 | I15: =SUMIFS(Transaction_Data[Quantity],Transaction_Data[HSN-Code],Inventory_Data[[#This Row],[HSN-Code]],Transaction_Data[Ware House No.],Inventory_Data[[#This Row],[Ware House No.]]) -> 10 | J15: =Inventory_Data[[#This Row],[Quantity in Stock]]*Inventory_Data[[#This Row],[Unit/Cost]] -> 230000 | K15: =_xlfn.XLOOKUP(Inventory_Data[[#This Row],[HSN-Code]],Product_Data[HSN Code.],Product_Data[Reorder Level],"") -> 10 | L15: =IF(Inventory_Data[[#This Row],[Reorder Level]]>=Inventory_Data[[#This Row],[Quantity in Stock]],"Yes","No") -> Yes
... C43: ASW-040 | D43: =_xlfn.XLOOKUP(Inventory_Data[[#This Row],[HSN-Code]],Product_Data[HSN Code.],Product_Data[Ware House No.],"") -> WH-0042 | E43: =_xlfn.XLOOKUP(C43,Product_Data[HSN Code.],Product_Data[Product],"") -> iPad 16 Pro Max | F43: =_xlfn.XLOOKUP(C43,Product_Data[HSN Code.],Product_Data[Category],"") -> Mobile Phone | G43: =_xlfn.XLOOKUP(C43,Product_Data[HSN Code.],Product_Data[Unit/Cost],"") -> 35000 | H43: =_xlfn.XLOOKUP(C43,Product_Data[HSN Code.],Product_Data[Selling Price],"") -> 110000 | I43: =SUMIFS(Transaction_Data[Quantity],Transaction_Data[HSN-Code],Inventory_Data[[#This Row],[HSN-Code]],Transaction_Data[Ware House No.],Inventory_Data[[#This Row],[Ware House No.]]) -> 2 | J43: =Inventory_Data[[#This Row],[Quantity in Stock]]*Inventory_Data[[#This Row],[Unit/Cost]] -> 70000 | K43: =_xlfn.XLOOKUP(Inventory_Data[[#This Row],[HSN-Code]],Product_Data[HSN Code.],Product_Data[Reorder Level],"") -> 10 | L43: =IF(Inventory_Data[[#This Row],[Reorder Level]]>=Inventory_Data[[#This Row],[Quantity in Stock]],"Yes","No") -> Yes

Sheet Purchase
C3: HSN Code. | D3: Product | E3: Category | F3: Vendor Comp. | G3: Contact Name | H3: E-mail ID | I3: Units | J3: Unit/Cost | K3: Total Value | L3: Order Date | M3: Arrival Date | N3: Status
C4: ASW-015 | D4: =_xlfn.XLOOKUP(C4,Inventory_Data[HSN-Code],Inventory_Data[Product],"") -> Asus Zenbook 14 | E4: =_xlfn.XLOOKUP(C4,Inventory_Data[HSN-Code],Inventory_Data[Category],"") -> Laptop | F4: =_xlfn.XLOOKUP(Purchase!C6,Vendor_Data[HSN Code.],Vendor_Data[Vendor Comp.],"") -> Foreighn Tech Distributers | G4: =_xlfn.XLOOKUP(C4,Vendor_Data[HSN Code.],Vendor_Data[Contact Name],"") -> John Smith | H4: =_xlfn.XLOOKUP(Purchase!C6,Vendor_Data[HSN Code.],Vendor_Data[E-mail ID],"") -> support@foreighntechdistributers.in | I4: 3 | J4: =_xlfn.XLOOKUP(C4,Inventory_Data[HSN-Code],Inventory_Data[Unit/Cost],"") -> 26000 | K4: =IF(I4="","",I4*J4) -> 78000 | L4: 45963 | M4: =IF(L4="","",L4+_xlfn.XLOOKUP(C4,Vendor_Data[HSN Code.],Vendor_Data[Delivery Time(in days)])) -> 45966 | N4: =IF(M4="","",IF(M4="","",IF(M4<TODAY(),"Completed","Pending"))) -> Completed
C5: ASW-016 | D5: =_xlfn.XLOOKUP(C5,Inventory_Data[HSN-Code],Inventory_Data[Product],"") -> iPhone 15 Pro Max | E5: =_xlfn.XLOOKUP(C5,Inventory_Data[HSN-Code],Inventory_Data[Category],"") -> Mobile Phone | F5: =_xlfn.XLOOKUP(Purchase!C7,Vendor_Data[HSN Code.],Vendor_Data[Vendor Comp.],"") -> Redington India Ltd | G5: =_xlfn.XLOOKUP(C5,Vendor_Data[HSN Code.],Vendor_Data[Contact Name],"") -> Dipti Sharma | H5: =_xlfn.XLOOKUP(Purchase!C7,Vendor_Data[HSN Code.],Vendor_Data[E-mail ID],"") -> support@redingtonindialtd.in | I5: 5 | J5: =_xlfn.XLOOKUP(C5,Inventory_Data[HSN-Code],Inventory_Data[Unit/Cost],"") -> 35000 | K5: =IF(I5="","",I5*J5) -> 175000 | L5: 45966 | M5: =IF(L5="","",L5+_xlfn.XLOOKUP(C5,Vendor_Data[HSN Code.],Vendor_Data[Delivery Time(in days)])) -> 45969 | N5: =IF(M5="","",IF(M5="","",IF(M5<TODAY(),"Completed","Pending"))) -> Completed
C6: ASW-005 | D6: =_xlfn.XLOOKUP(C6,Inventory_Data[HSN-Code],Inventory_Data[Product],"") -> One Plus 12 | E6: =_xlfn.XLOOKUP(C6,Inventory_Data[HSN-Code],Inventory_Data[Category],"") -> Mobile Phone | F6: =_xlfn.XLOOKUP(Purchase!C4,Vendor_Data[HSN Code.],Vendor_Data[Vendor Comp.],"") -> Foreighn Tech Distributers | G6: =_xlfn.XLOOKUP(C6,Vendor_Data[HSN Code.],Vendor_Data[Contact Name],"") -> John Smith | H6: =_xlfn.XLOOKUP(Purchase!C4,Vendor_Data[HSN Code.],Vendor_Data[E-mail ID],"") -> support@foreighntechdistributers.in | I6: 5 | J6: =_xlfn.XLOOKUP(C6,Inventory_Data[HSN-Code],Inventory_Data[Unit/Cost],"") -> 11000 | K6: =IF(I6="","",I6*J6) -> 55000 | L6: 45963 | M6: =IF(L6="","",L6+_xlfn.XLOOKUP(C6,Vendor_Data[HSN Code.],Vendor_Data[Delivery Time(in days)])) -> 45970 | N6: =IF(M6="","",IF(M6="","",IF(M6<TODAY(),"Completed","Pending"))) -> Completed
C7: ASW-013 | D7: =_xlfn.XLOOKUP(C7,Inventory_Data[HSN-Code],Inventory_Data[Product],"") -> MacBook Pro M3 Max 16 | E7: =_xlfn.XLOOKUP(C7,Inventory_Data[HSN-Code],Inventory_Data[Category],"") -> Laptop | F7: =_xlfn.XLOOKUP(Purchase!C5,Vendor_Data[HSN Code.],Vendor_Data[Vendor Comp.],"") -> Redington India Ltd | G7: =_xlfn.XLOOKUP(C7,Vendor_Data[HSN Code.],Vendor_Data[Contact Name],"") -> Dipti Sharma | H7: =_xlfn.XLOOKUP(Purchase!C5,Vendor_Data[HSN Code.],Vendor_Data[E-mail ID],"") -> support@redingtonindialtd.in | I7: 4 | J7: =_xlfn.XLOOKUP(C7,Inventory_Data[HSN-Code],Inventory_Data[Unit/Cost],"") -> 40000 | K7: =IF(I7="","",I7*J7) -> 160000 | L7: 45963 | M7: =IF(L7="","",L7+_xlfn.XLOOKUP(C7,Vendor_Data[HSN Code.],Vendor_Data[Delivery Time(in days)])) -> 45970 | N7: =IF(M7="","",IF(M7="","",IF(M7<TODAY(),"Completed","Pending"))) -> Completed
C8: ASW-017 | D8: =_xlfn.XLOOKUP(C8,Inventory_Data[HSN-Code],Inventory_Data[Product],"") -> Dell Alienware | E8: =_xlfn.XLOOKUP(C8,Inventory_Data[HSN-Code],Inventory_Data[Category],"") -> Laptop | F8: =_xlfn.XLOOKUP(Purchase!C8,Vendor_Data[HSN Code.],Vendor_Data[Vendor Comp.],"") -> Tech Distributers | G8: =_xlfn.XLOOKUP(C8,Vendor_Data[HSN Code.],Vendor_Data[Contact Name],"") -> Amit Khandal | H8: =_xlfn.XLOOKUP(Purchase!C8,Vendor_Data[HSN Code.],Vendor_Data[E-mail ID],"") -> support@techdistributers.in | I8: 2 | J8: =_xlfn.XLOOKUP(C8,Inventory_Data[HSN-Code],Inventory_Data[Unit/Cost],"") -> 26000 | K8: =IF(I8="","",I8*J8) -> 52000 | L8: 45968 | M8: =IF(L8="","",L8+_xlfn.XLOOKUP(C8,Vendor_Data[HSN Code.],Vendor_Data[Delivery Time(in days)])) -> 45974 | N8: =IF(M8="","",IF(M8="","",IF(M8<TODAY(),"Completed","Pending"))) -> Completed
C9: ASW-018 | D9: =_xlfn.XLOOKUP(C9,Inventory_Data[HSN-Code],Inventory_Data[Product],"") -> Samsung Galaxy S24 Ultra | E9: =_xlfn.XLOOKUP(C9,Inventory_Data[HSN-Code],Inventory_Data[Category],"") -> Mobile Phone | F9: =_xlfn.XLOOKUP(Purchase!C9,Vendor_Data[HSN Code.],Vendor_Data[Vendor Comp.],"") -> K&L Distributers | G9: =_xlfn.XLOOKUP(C9,Vendor_Data[HSN Code.],Vendor_Data[Contact Name],"") -> Leoroy Hanlon | H9: =_xlfn.XLOOKUP(Purchase!C9,Vendor_Data[HSN Code.],Vendor_Data[E-mail ID],"") -> support@k&ldistributers.in | I9: 3 | J9: =_xlfn.XLOOKUP(C9,Inventory_Data[HSN-Code],Inventory_Data[Unit/Cost],"") -> 22000 | K9: =IF(I9="","",I9*J9) -> 66000 | L9: 45971 | M9: =IF(L9="","",L9+_xlfn.XLOOKUP(C9,Vendor_Data[HSN Code.],Vendor_Data[Delivery Time(in days)])) -> 45974 | N9: =IF(M9="","",IF(M9="","",IF(M9<TODAY(),"Completed","Pending"))) -> Completed
C10: ASW-020 | D10: =_xlfn.XLOOKUP(C10,Inventory_Data[HSN-Code],Inventory_Data[Product],"") -> Xiaomi 14 Pro | E10: =_xlfn.XLOOKUP(C10,Inventory_Data[HSN-Code],Inventory_Data[Category],"") -> Mobile Phone | F10: =_xlfn.XLOOKUP(Purchase!C10,Vendor_Data[HSN Code.],Vendor_Data[Vendor Comp.],"") -> Savex Technologies | G10: =_xlfn.XLOOKUP(C10,Vendor_Data[HSN Code.],Vendor_Data[Contact Name],"") -> Ashok Ghalot | H10: =_xlfn.XLOOKUP(Purchase!C10,Vendor_Data[HSN Code.],Vendor_Data[E-mail ID],"") -> support@savextechnologies.in | I10: 7 | J10: =_xlfn.XLOOKUP(C10,Inventory_Data[HSN-Code],Inventory_Data[Unit/Cost],"") -> 11000 | K10: =IF(I10="","",I10*J10) -> 77000 | L10: 45976 | M10: =IF(L10="","",L10+_xlfn.XLOOKUP(C10,Vendor_Data[HSN Code.],Vendor_Data[Delivery Time(in days)])) -> 45980 | N10: =IF(M10="","",IF(M10="","",IF(M10<TODAY(),"Completed","Pending"))) -> Completed
C11: ASW-023 | D11: =_xlfn.XLOOKUP(C11,Inventory_Data[HSN-Code],Inventory_Data[Product],"") -> iPad Air | E11: =_xlfn.XLOOKUP(C11,Inventory_Data[HSN-Code],Inventory_Data[Category],"") -> Tablet | F11: =_xlfn.XLOOKUP(Purchase!C11,Vendor_Data[HSN Code.],Vendor_Data[Vendor Comp.],"") -> K&L Distributers | G11: =_xlfn.XLOOKUP(C11,Vendor_Data[HSN Code.],Vendor_Data[Contact Name],"") -> Leoroy Hanlon | H11: =_xlfn.XLOOKUP(Purchase!C11,Vendor_Data[HSN Code.],Vendor_Data[E-mail ID],"") -> support@k&ldistributers.in | I11: 8 | J11: =_xlfn.XLOOKUP(C11,Inventory_Data[HSN-Code],Inventory_Data[Unit/Cost],"") -> 23000 | K11: =IF(I11="","",I11*J11) -> 184000 | L11: 45981 | M11: =IF(L11="","",L11+_xlfn.XLOOKUP(C11,Vendor_Data[HSN Code.],Vendor_Data[Delivery Time(in days)])) -> 45986 | N11: =IF(M11="","",IF(M11="","",IF(M11<TODAY(),"Completed","Pending"))) -> Completed
C12: ASW-025 | D12: =_xlfn.XLOOKUP(C12,Inventory_Data[HSN-Code],Inventory_Data[Product],"") -> Samsung Smart Led TV | E12: =_xlfn.XLOOKUP(C12,Inventory_Data[HSN-Code],Inventory_Data[Category],"") -> Led TV | F12: =_xlfn.XLOOKUP(Purchase!C13,Vendor_Data[HSN Code.],Vendor_Data[Vendor Comp.],"") -> Halo Tech Ltd | G12: =_xlfn.XLOOKUP(C12,Vendor_Data[HSN Code.],Vendor_Data[Contact Name],"") -> John Smith | H12: =_xlfn.XLOOKUP(Purchase!C13,Vendor_Data[HSN Code.],Vendor_Data[E-mail ID],"") -> support@halotechltd.in | I12: 10 | J12: =_xlfn.XLOOKUP(C12,Inventory_Data[HSN-Code],Inventory_Data[Unit/Cost],"") -> 25000 | K12: =IF(I12="","",I12*J12) -> 250000 | L12: 45992 | M12: =IF(L12="","",L12+_xlfn.XLOOKUP(C12,Vendor_Data[HSN Code.],Vendor_Data[Delivery Time(in days)])) -> 45994 | N12: =IF(M12="","",IF(M12="","",IF(M12<TODAY(),"Completed","Pending"))) -> Completed
C13: ASW-024 | D13: =_xlfn.XLOOKUP(C13,Inventory_Data[HSN-Code],Inventory_Data[Product],"") -> One Plus Led TV | E13: =_xlfn.XLOOKUP(C13,Inventory_Data[HSN-Code],Inventory_Data[Category],"") -> Led TV | F13: =_xlfn.XLOOKUP(Purchase!C12,Vendor_Data[HSN Code.],Vendor_Data[Vendor Comp.],"") -> Foreighn Tech Distributers | G13: =_xlfn.XLOOKUP(C13,Vendor_Data[HSN Code.],Vendor_Data[Contact Name],"") -> Sahid Ali khan | H13: =_xlfn.XLOOKUP(Purchase!C12,Vendor_Data[HSN Code.],Vendor_Data[E-mail ID],"") -> support@foreighntechdistributers.in | I13: 10 | J13: =_xlfn.XLOOKUP(C13,Inventory_Data[HSN-Code],Inventory_Data[Unit/Cost],"") -> 21000 | K13: =IF(I13="","",I13*J13) -> 210000 | L13: 45991 | M13: =IF(L13="","",L13+_xlfn.XLOOKUP(C13,Vendor_Data[HSN Code.],Vendor_Data[Delivery Time(in days)])) -> 45997 | N13: =IF(M13="","",IF(M13="","",IF(M13<TODAY(),"Completed","Pending"))) -> Completed
C14: ASW-026 | D14: =_xlfn.XLOOKUP(C14,Inventory_Data[HSN-Code],Inventory_Data[Product],"") -> MacBook Air M2 13 | E14: =_xlfn.XLOOKUP(C14,Inventory_Data[HSN-Code],Inventory_Data[Category],"") -> Laptop | F14: =_xlfn.XLOOKUP(Purchase!C14,Vendor_Data[HSN Code.],Vendor_Data[Vendor Comp.],"") -> Tech Distributers | G14: =_xlfn.XLOOKUP(C14,Vendor_Data[HSN Code.],Vendor_Data[Contact Name],"") -> Amit Khandal | H14: =_xlfn.XLOOKUP(Purchase!C14,Vendor_Data[HSN Code.],Vendor_Data[E-mail ID],"") -> support@techdistributers.in | I14: 15 | J14: =_xlfn.XLOOKUP(C14,Inventory_Data[HSN-Code],Inventory_Data[Unit/Cost],"") -> 50000 | K14: =IF(I14="","",I14*J14) -> 750000 | L14: 46001 | M14: =IF(L14="","",L14+_xlfn.XLOOKUP(C14,Vendor_Data[HSN Code.],Vendor_Data[Delivery Time(in days)])) -> 46006 | N14: =IF(M14="","",IF(M14="","",IF(M14<TODAY(),"Completed","Pending"))) -> Completed
C15: ASW-029 | D15: =_xlfn.XLOOKUP(C15,Inventory_Data[HSN-Code],Inventory_Data[Product],"") -> Samsung Galaxy S24+ | E15: =_xlfn.XLOOKUP(C15,Inventory_Data[HSN-Code],Inventory_Data[Category],"") -> Mobile Phone | F15: =_xlfn.XLOOKUP(Purchase!C15,Vendor_Data[HSN Code.],Vendor_Data[Vendor Comp.],"") -> Savex Technologies | G15: =_xlfn.XLOOKUP(C15,Vendor_Data[HSN Code.],Vendor_Data[Contact Name],"") -> Ashok Ghalot | H15: =_xlfn.XLOOKUP(Purchase!C15,Vendor_Data[HSN Code.],Vendor_Data[E-mail ID],"") -> support@savextechnologies.in | I15: 10 | J15: =_xlfn.XLOOKUP(C15,Inventory_Data[HSN-Code],Inventory_Data[Unit/Cost],"") -> 50000 | K15: =IF(I15="","",I15*J15) -> 500000 | L15: 46006 | M15: =IF(L15="","",L15+_xlfn.XLOOKUP(C15,Vendor_Data[HSN Code.],Vendor_Data[Delivery Time(in days)])) -> 46012 | N15: =IF(M15="","",IF(M15="","",IF(M15<TODAY(),"Completed","Pending"))) -> Completed
C16: ASW-032 | D16: =_xlfn.XLOOKUP(C16,Inventory_Data[HSN-Code],Inventory_Data[Product],"") -> Samsung Android TV | E16: =_xlfn.XLOOKUP(C16,Inventory_Data[HSN-Code],Inventory_Data[Category],"") -> Led TV | F16: =_xlfn.XLOOKUP(Purchase!C17,Vendor_Data[HSN Code.],Vendor_Data[Vendor Comp.],"") -> Tech Distributers | G16: =_xlfn.XLOOKUP(C16,Vendor_Data[HSN Code.],Vendor_Data[Contact Name],"") -> Ashok Ghalot | H16: =_xlfn.XLOOKUP(Purchase!C17,Vendor_Data[HSN Code.],Vendor_Data[E-mail ID],"") -> support@techdistributers.in | I16: 10 | J16: =_xlfn.XLOOKUP(C16,Inventory_Data[HSN-Code],Inventory_Data[Unit/Cost],"") -> 25000 | K16: =IF(I16="","",I16*J16) -> 250000 | L16: 46008 | M16: =IF(L16="","",L16+_xlfn.XLOOKUP(C16,Vendor_Data[HSN Code.],Vendor_Data[Delivery Time(in days)])) -> 46012 | N16: =IF(M16="","",IF(M16="","",IF(M16<TODAY(),"Completed","Pending"))) -> Completed
C17: ASW-035 | D17: =_xlfn.XLOOKUP(C17,Inventory_Data[HSN-Code],Inventory_Data[Product],"") -> Sony Bravia Smart 4K | E17: =_xlfn.XLOOKUP(C17,Inventory_Data[HSN-Code],Inventory_Data[Category],"") -> Led TV | F17: =_xlfn.XLOOKUP(Purchase!C18,Vendor_Data[HSN Code.],Vendor_Data[Vendor Comp.],"") -> Iris Computers Ltd | G17: =_xlfn.XLOOKUP(C17,Vendor_Data[HSN Code.],Vendor_Data[Contact Name],"") -> Amit Khandal | H17: =_xlfn.XLOOKUP(Purchase!C18,Vendor_Data[HSN Code.],Vendor_Data[E-mail ID],"") -> support@iriscomputersltd.in | I17: 10 | J17: =_xlfn.XLOOKUP(C17,Inventory_Data[HSN-Code],Inventory_Data[Unit/Cost],"") -> 33000 | K17: =IF(I17="","",I17*J17) -> 330000 | L17: 46008 | M17: =IF(L17="","",L17+_xlfn.XLOOKUP(C17,Vendor_Data[HSN Code.],Vendor_Data[Delivery Time(in days)])) -> 46012 | N17: =IF(M17="","",IF(M17="","",IF(M17<TODAY(),"Completed","Pending"))) -> Completed
C18: ASW-030 | D18: =_xlfn.XLOOKUP(C18,Inventory_Data[HSN-Code],Inventory_Data[Product],"") -> One Plus Ultra | E18: =_xlfn.XLOOKUP(C18,Inventory_Data[HSN-Code],Inventory_Data[Category],"") -> Mobile Phone | F18: =_xlfn.XLOOKUP(Purchase!C16,Vendor_Data[HSN Code.],Vendor_Data[Vendor Comp.],"") -> Savex Technologies | G18: =_xlfn.XLOOKUP(C18,Vendor_Data[HSN Code.],Vendor_Data[Contact Name],"") -> Richie Alexander | H18: =_xlfn.XLOOKUP(Purchase!C16,Vendor_Data[HSN Code.],Vendor_Data[E-mail ID],"") -> support@savextechnologies.in | I18: 9 | J18: =_xlfn.XLOOKUP(C18,Inventory_Data[HSN-Code],Inventory_Data[Unit/Cost],"") -> 11000 | K18: =IF(I18="","",I18*J18) -> 99000 | L18: 46006 | M18: =IF(L18="","",L18+_xlfn.XLOOKUP(C18,Vendor_Data[HSN Code.],Vendor_Data[Delivery Time(in days)])) -> 46013 | N18: =IF(M18="","",IF(M18="","",IF(M18<TODAY(),"Completed","Pending"))) -> Completed
C19: ASW-037 | D19: =_xlfn.XLOOKUP(C19,Inventory_Data[HSN-Code],Inventory_Data[Product],"") -> Google Smart TV | E19: =_xlfn.XLOOKUP(C19,Inventory_Data[HSN-Code],Inventory_Data[Category],"") -> Led TV | F19: =_xlfn.XLOOKUP(Purchase!C20,Vendor_Data[HSN Code.],Vendor_Data[Vendor Comp.],"") -> Iris Computers Ltd | G19: =_xlfn.XLOOKUP(C19,Vendor_Data[HSN Code.],Vendor_Data[Contact Name],"") -> Dipti Sharma | H19: =_xlfn.XLOOKUP(Purchase!C20,Vendor_Data[HSN Code.],Vendor_Data[E-mail ID],"") -> support@iriscomputersltd.in | I19: 9 | J19: =_xlfn.XLOOKUP(C19,Inventory_Data[HSN-Code],Inventory_Data[Unit/Cost],"") -> 23000 | K19: =IF(I19="","",I19*J19) -> 207000 | L19: 46042 | M19: =IF(L19="","",L19+_xlfn.XLOOKUP(C19,Vendor_Data[HSN Code.],Vendor_Data[Delivery Time(in days)])) -> 46044 | N19: =IF(M19="","",IF(M19="","",IF(M19<TODAY(),"Completed","Pending"))) -> Pending
C20: ASW-038 | D20: =_xlfn.XLOOKUP(C20,Inventory_Data[HSN-Code],Inventory_Data[Product],"") -> iPad 16 | E20: =_xlfn.XLOOKUP(C20,Inventory_Data[HSN-Code],Inventory_Data[Category],"") -> Mobile Phone | F20: =_xlfn.XLOOKUP(Purchase!C21,Vendor_Data[HSN Code.],Vendor_Data[Vendor Comp.],"") -> Redington India Ltd | G20: =_xlfn.XLOOKUP(C20,Vendor_Data[HSN Code.],Vendor_Data[Contact Name],"") -> Richie Alexander | H20: =_xlfn.XLOOKUP(Purchase!C21,Vendor_Data[HSN Code.],Vendor_Data[E-mail ID],"") -> support@redingtonindialtd.in | I20: 9 | J20: =_xlfn.XLOOKUP(C20,Inventory_Data[HSN-Code],Inventory_Data[Unit/Cost],"") -> 45000 | K20: =IF(I20="","",I20*J20) -> 405000 | L20: 46042 | M20: =IF(L20="","",L20+_xlfn.XLOOKUP(C20,Vendor_Data[HSN Code.],Vendor_Data[Delivery Time(in days)])) -> 46044 | N20: =IF(M20="","",IF(M20="","",IF(M20<TODAY(),"Completed","Pending"))) -> Pending
C21: ASW-040 | D21: =_xlfn.XLOOKUP(C21,Inventory_Data[HSN-Code],Inventory_Data[Product],"") -> iPad 16 Pro Max | E21: =_xlfn.XLOOKUP(C21,Inventory_Data[HSN-Code],Inventory_Data[Category],"") -> Mobile Phone | F21: =_xlfn.XLOOKUP(Purchase!C22,Vendor_Data[HSN Code.],Vendor_Data[Vendor Comp.],"") -> Halo Tech Ltd | G21: =_xlfn.XLOOKUP(C21,Vendor_Data[HSN Code.],Vendor_Data[Contact Name],"") -> Dipti Sharma | H21: =_xlfn.XLOOKUP(Purchase!C22,Vendor_Data[HSN Code.],Vendor_Data[E-mail ID],"") -> support@halotechltd.in | I21: 10 | J21: =_xlfn.XLOOKUP(C21,Inventory_Data[HSN-Code],Inventory_Data[Unit/Cost],"") -> 35000 | K21: =IF(I21="","",I21*J21) -> 350000 | L21: 46042 | M21: =IF(L21="","",L21+_xlfn.XLOOKUP(C21,Vendor_Data[HSN Code.],Vendor_Data[Delivery Time(in days)])) -> 46046 | N21: =IF(M21="","",IF(M21="","",IF(M21<TODAY(),"Completed","Pending"))) -> Pending
C22: ASW-036 | D22: =_xlfn.XLOOKUP(C22,Inventory_Data[HSN-Code],Inventory_Data[Product],"") -> Samsung F23 Plus | E22: =_xlfn.XLOOKUP(C22,Inventory_Data[HSN-Code],Inventory_Data[Category],"") -> Mobile Phone | F22: =_xlfn.XLOOKUP(Purchase!C19,Vendor_Data[HSN Code.],Vendor_Data[Vendor Comp.],"") -> Redington India Ltd | G22: =_xlfn.XLOOKUP(C22,Vendor_Data[HSN Code.],Vendor_Data[Contact Name],"") -> Sahid Ali khan | H22: =_xlfn.XLOOKUP(Purchase!C19,Vendor_Data[HSN Code.],Vendor_Data[E-mail ID],"") -> support@redingtonindialtd.in | I22: 11 | J22: =_xlfn.XLOOKUP(C22,Inventory_Data[HSN-Code],Inventory_Data[Unit/Cost],"") -> 20000 | K22: =IF(I22="","",I22*J22) -> 220000 | L22: 46042 | M22: =IF(L22="","",L22+_xlfn.XLOOKUP(C22,Vendor_Data[HSN Code.],Vendor_Data[Delivery Time(in days)])) -> 46047 | N22: =IF(M22="","",IF(M22="","",IF(M22<TODAY(),"Completed","Pending"))) -> Pending
D23: =_xlfn.XLOOKUP(C23,Inventory_Data[HSN-Code],Inventory_Data[Product],"") | E23: =_xlfn.XLOOKUP(C23,Inventory_Data[HSN-Code],Inventory_Data[Category],"") | F23: =_xlfn.XLOOKUP(Purchase!C23,Vendor_Data[HSN Code.],Vendor_Data[Vendor Comp.],"") | G23: =_xlfn.XLOOKUP(C23,Vendor_Data[HSN Code.],Vendor_Data[Contact Name],"") | H23: =_xlfn.XLOOKUP(Purchase!C23,Vendor_Data[HSN Code.],Vendor_Data[E-mail ID],"") | J23: =_xlfn.XLOOKUP(C23,Inventory_Data[HSN-Code],Inventory_Data[Unit/Cost],"") | K23: =IF(I23="","",I23*J23) | M23: =IF(L23="","",L23+_xlfn.XLOOKUP(C23,Vendor_Data[HSN Code.],Vendor_Data[Delivery Time(in days)])) | N23: =IF(M23="","",IF(M23<TODAY(),"Completed","Pending"))
D24: =_xlfn.XLOOKUP(C24,Inventory_Data[HSN-Code],Inventory_Data[Product],"") | E24: =_xlfn.XLOOKUP(C24,Inventory_Data[HSN-Code],Inventory_Data[Category],"") | F24: =_xlfn.XLOOKUP(Purchase!C24,Vendor_Data[HSN Code.],Vendor_Data[Vendor Comp.],"") | G24: =_xlfn.XLOOKUP(C24,Vendor_Data[HSN Code.],Vendor_Data[Contact Name],"") | H24: =_xlfn.XLOOKUP(Purchase!C24,Vendor_Data[HSN Code.],Vendor_Data[E-mail ID],"") | J24: =_xlfn.XLOOKUP(C24,Inventory_Data[HSN-Code],Inventory_Data[Unit/Cost],"") | K24: =IF(I24="","",I24*J24) | M24: =IF(L24="","",L24+_xlfn.XLOOKUP(C24,Vendor_Data[HSN Code.],Vendor_Data[Delivery Time(in days)])) | N24: =IF(M24="","",IF(M24<TODAY(),"Completed","Pending"))
D25: =_xlfn.XLOOKUP(C25,Inventory_Data[HSN-Code],Inventory_Data[Product],"") | E25: =_xlfn.XLOOKUP(C25,Inventory_Data[HSN-Code],Inventory_Data[Category],"") | F25: =_xlfn.XLOOKUP(Purchase!C25,Vendor_Data[HSN Code.],Vendor_Data[Vendor Comp.],"") | G25: =_xlfn.XLOOKUP(C25,Vendor_Data[HSN Code.],Vendor_Data[Contact Name],"") | H25: =_xlfn.XLOOKUP(Purchase!C25,Vendor_Data[HSN Code.],Vendor_Data[E-mail ID],"") | J25: =_xlfn.XLOOKUP(C25,Inventory_Data[HSN-Code],Inventory_Data[Unit/Cost],"") | K25: =IF(I25="","",I25*J25) | M25: =IF(L25="","",L25+_xlfn.XLOOKUP(C25,Vendor_Data[HSN Code.],Vendor_Data[Delivery Time(in days)])) | N25: =IF(M25="","",IF(M25<TODAY(),"Completed","Pending"))
D26: =_xlfn.XLOOKUP(C26,Inventory_Data[HSN-Code],Inventory_Data[Product],"") | E26: =_xlfn.XLOOKUP(C26,Inventory_Data[HSN-Code],Inventory_Data[Category],"") | F26: =_xlfn.XLOOKUP(Purchase!C26,Vendor_Data[HSN Code.],Vendor_Data[Vendor Comp.],"") | G26: =_xlfn.XLOOKUP(C26,Vendor_Data[HSN Code.],Vendor_Data[Contact Name],"") | H26: =_xlfn.XLOOKUP(Purchase!C26,Vendor_Data[HSN Code.],Vendor_Data[E-mail ID],"") | J26: =_xlfn.XLOOKUP(C26,Inventory_Data[HSN-Code],Inventory_Data[Unit/Cost],"") | K26: =IF(I26="","",I26*J26) | M26: =IF(L26="","",L26+_xlfn.XLOOKUP(C26,Vendor_Data[HSN Code.],Vendor_Data[Delivery Time(in days)])) | N26: =IF(M26="","",IF(M26<TODAY(),"Completed","Pending"))
D27: =_xlfn.XLOOKUP(C27,Inventory_Data[HSN-Code],Inventory_Data[Product],"") | E27: =_xlfn.XLOOKUP(C27,Inventory_Data[HSN-Code],Inventory_Data[Category],"") | F27: =_xlfn.XLOOKUP(Purchase!C27,Vendor_Data[HSN Code.],Vendor_Data[Vendor Comp.],"") | G27: =_xlfn.XLOOKUP(C27,Vendor_Data[HSN Code.],Vendor_Data[Contact Name],"") | H27: =_xlfn.XLOOKUP(Purchase!C27,Vendor_Data[HSN Code.],Vendor_Data[E-mail ID],"") | J27: =_xlfn.XLOOKUP(C27,Inventory_Data[HSN-Code],Inventory_Data[Unit/Cost],"") | K27: =IF(I27="","",I27*J27) | M27: =IF(L27="","",L27+_xlfn.XLOOKUP(C27,Vendor_Data[HSN Code.],Vendor_Data[Delivery Time(in days)])) | N27: =IF(M27="","",IF(M27<TODAY(),"Completed","Pending"))
D28: =_xlfn.XLOOKUP(C28,Inventory_Data[HSN-Code],Inventory_Data[Product],"") | E28: =_xlfn.XLOOKUP(C28,Inventory_Data[HSN-Code],Inventory_Data[Category],"") | F28: =_xlfn.XLOOKUP(Purchase!C28,Vendor_Data[HSN Code.],Vendor_Data[Vendor Comp.],"") | G28: =_xlfn.XLOOKUP(C28,Vendor_Data[HSN Code.],Vendor_Data[Contact Name],"") | H28: =_xlfn.XLOOKUP(Purchase!C28,Vendor_Data[HSN Code.],Vendor_Data[E-mail ID],"") | J28: =_xlfn.XLOOKUP(C28,Inventory_Data[HSN-Code],Inventory_Data[Unit/Cost],"") | K28: =IF(I28="","",I28*J28) | M28: =IF(L28="","",L28+_xlfn.XLOOKUP(C28,Vendor_Data[HSN Code.],Vendor_Data[Delivery Time(in days)])) | N28: =IF(M28="","",IF(M28<TODAY(),"Completed","Pending"))
D29: =_xlfn.XLOOKUP(C29,Inventory_Data[HSN-Code],Inventory_Data[Product],"") | E29: =_xlfn.XLOOKUP(C29,Inventory_Data[HSN-Code],Inventory_Data[Category],"") | F29: =_xlfn.XLOOKUP(Purchase!C29,Vendor_Data[HSN Code.],Vendor_Data[Vendor Comp.],"") | G29: =_xlfn.XLOOKUP(C29,Vendor_Data[HSN Code.],Vendor_Data[Contact Name],"") | H29: =_xlfn.XLOOKUP(Purchase!C29,Vendor_Data[HSN Code.],Vendor_Data[E-mail ID],"") | J29: =_xlfn.XLOOKUP(C29,Inventory_Data[HSN-Code],Inventory_Data[Unit/Cost],"") | K29: =IF(I29="","",I29*J29) | M29: =IF(L29="","",L29+_xlfn.XLOOKUP(C29,Vendor_Data[HSN Code.],Vendor_Data[Delivery Time(in days)])) | N29: =IF(M29="","",IF(M29<TODAY(),"Completed","Pending"))
D30: =_xlfn.XLOOKUP(C30,Inventory_Data[HSN-Code],Inventory_Data[Product],"") | E30: =_xlfn.XLOOKUP(C30,Inventory_Data[HSN-Code],Inventory_Data[Category],"") | F30: =_xlfn.XLOOKUP(Purchase!C30,Vendor_Data[HSN Code.],Vendor_Data[Vendor Comp.],"") | G30: =_xlfn.XLOOKUP(C30,Vendor_Data[HSN Code.],Vendor_Data[Contact Name],"") | H30: =_xlfn.XLOOKUP(Purchase!C30,Vendor_Data[HSN Code.],Vendor_Data[E-mail ID],"") | J30: =_xlfn.XLOOKUP(C30,Inventory_Data[HSN-Code],Inventory_Data[Unit/Cost],"") | K30: =IF(I30="","",I30*J30) | M30: =IF(L30="","",L30+_xlfn.XLOOKUP(C30,Vendor_Data[HSN Code.],Vendor_Data[Delivery Time(in days)])) | N30: =IF(M30="","",IF(M30<TODAY(),"Completed","Pending"))
D31: =_xlfn.XLOOKUP(C31,Inventory_Data[HSN-Code],Inventory_Data[Product],"") | E31: =_xlfn.XLOOKUP(C31,Inventory_Data[HSN-Code],Inventory_Data[Category],"") | F31: =_xlfn.XLOOKUP(Purchase!C31,Vendor_Data[HSN Code.],Vendor_Data[Vendor Comp.],"") | G31: =_xlfn.XLOOKUP(C31,Vendor_Data[HSN Code.],Vendor_Data[Contact Name],"") | H31: =_xlfn.XLOOKUP(Purchase!C31,Vendor_Data[HSN Code.],Vendor_Data[E-mail ID],"") | J31: =_xlfn.XLOOKUP(C31,Inventory_Data[HSN-Code],Inventory_Data[Unit/Cost],"") | K31: =IF(I31="","",I31*J31) | M31: =IF(L31="","",L31+_xlfn.XLOOKUP(C31,Vendor_Data[HSN Code.],Vendor_Data[Delivery Time(in days)])) | N31: =IF(M31="","",IF(M31<TODAY(),"Completed","Pending"))
D32: =_xlfn.XLOOKUP(C32,Inventory_Data[HSN-Code],Inventory_Data[Product],"") | E32: =_xlfn.XLOOKUP(C32,Inventory_Data[HSN-Code],Inventory_Data[Category],"") | F32: =_xlfn.XLOOKUP(Purchase!C32,Vendor_Data[HSN Code.],Vendor_Data[Vendor Comp.],"") | G32: =_xlfn.XLOOKUP(C32,Vendor_Data[HSN Code.],Vendor_Data[Contact Name],"") | H32: =_xlfn.XLOOKUP(Purchase!C32,Vendor_Data[HSN Code.],Vendor_Data[E-mail ID],"") | J32: =_xlfn.XLOOKUP(C32,Inventory_Data[HSN-Code],Inventory_Data[Unit/Cost],"") | K32: =IF(I32="","",I32*J32) | M32: =IF(L32="","",L32+_xlfn.XLOOKUP(C32,Vendor_Data[HSN Code.],Vendor_Data[Delivery Time(in days)])) | N32: =IF(M32="","",IF(M32<TODAY(),"Completed","Pending"))
D33: =_xlfn.XLOOKUP(C33,Inventory_Data[HSN-Code],Inventory_Data[Product],"") | E33: =_xlfn.XLOOKUP(C33,Inventory_Data[HSN-Code],Inventory_Data[Category],"") | F33: =_xlfn.XLOOKUP(Purchase!C33,Vendor_Data[HSN Code.],Vendor_Data[Vendor Comp.],"") | G33: =_xlfn.XLOOKUP(C33,Vendor_Data[HSN Code.],Vendor_Data[Contact Name],"") | H33: =_xlfn.XLOOKUP(Purchase!C33,Vendor_Data[HSN Code.],Vendor_Data[E-mail ID],"") | J33: =_xlfn.XLOOKUP(C33,Inventory_Data[HSN-Code],Inventory_Data[Unit/Cost],"") | K33: =IF(I33="","",I33*J33) | M33: =IF(L33="","",L33+_xlfn.XLOOKUP(C33,Vendor_Data[HSN Code.],Vendor_Data[Delivery Time(in days)])) | N33: =IF(M33="","",IF(M33<TODAY(),"Completed","Pending"))
D34: =_xlfn.XLOOKUP(C34,Inventory_Data[HSN-Code],Inventory_Data[Product],"") | E34: =_xlfn.XLOOKUP(C34,Inventory_Data[HSN-Code],Inventory_Data[Category],"") | F34: =_xlfn.XLOOKUP(Purchase!C34,Vendor_Data[HSN Code.],Vendor_Data[Vendor Comp.],"") | G34: =_xlfn.XLOOKUP(C34,Vendor_Data[HSN Code.],Vendor_Data[Contact Name],"") | H34: =_xlfn.XLOOKUP(Purchase!C34,Vendor_Data[HSN Code.],Vendor_Data[E-mail ID],"") | J34: =_xlfn.XLOOKUP(C34,Inventory_Data[HSN-Code],Inventory_Data[Unit/Cost],"") | K34: =IF(I34="","",I34*J34) | M34: =IF(L34="","",L34+_xlfn.XLOOKUP(C34,Vendor_Data[HSN Code.],Vendor_Data[Delivery Time(in days)])) | N34: =IF(M34="","",IF(M34<TODAY(),"Completed","Pending"))
... D77: =_xlfn.XLOOKUP(C77,Inventory_Data[HSN-Code],Inventory_Data[Product],"") | E77: =_xlfn.XLOOKUP(C77,Inventory_Data[HSN-Code],Inventory_Data[Category],"") | F77: =_xlfn.XLOOKUP(Purchase!C77,Vendor_Data[HSN Code.],Vendor_Data[Vendor Comp.],"") | G77: =_xlfn.XLOOKUP(C77,Vendor_Data[HSN Code.],Vendor_Data[Contact Name],"") | H77: =_xlfn.XLOOKUP(Purchase!C77,Vendor_Data[HSN Code.],Vendor_Data[E-mail ID],"") | J77: =_xlfn.XLOOKUP(C77,Inventory_Data[HSN-Code],Inventory_Data[Unit/Cost],"") | K77: =IF(I77="","",I77*J77) | M77: =IF(L77="","",L77+_xlfn.XLOOKUP(C77,Vendor_Data[HSN Code.],Vendor_Data[Delivery Time(in days)])) | N77: =IF(M77="","",IF(M77<TODAY(),"Completed","Pending"))
D78: =_xlfn.XLOOKUP(C78,Inventory_Data[HSN-Code],Inventory_Data[Product],"") | F78: =_xlfn.XLOOKUP(Purchase!C78,Vendor_Data[HSN Code.],Vendor_Data[Vendor Comp.],"") | G78: =_xlfn.XLOOKUP(C78,Vendor_Data[HSN Code.],Vendor_Data[Contact Name],"") | J78: =_xlfn.XLOOKUP(C78,Inventory_Data[HSN-Code],Inventory_Data[Unit/Cost],"") | K78: =IF(I78="","",I78*J78) | M78: =IF(L78="","",L78+_xlfn.XLOOKUP(C78,Vendor_Data[HSN Code.],Vendor_Data[Delivery Time(in days)])) | N78: =IF(M78="","",IF(M78<TODAY(),"Completed","Pending"))
D79: =_xlfn.XLOOKUP(C79,Inventory_Data[HSN-Code],Inventory_Data[Product],"") | F79: =_xlfn.XLOOKUP(Purchase!C79,Vendor_Data[HSN Code.],Vendor_Data[Vendor Comp.],"") | G79: =_xlfn.XLOOKUP(C79,Vendor_Data[HSN Code.],Vendor_Data[Contact Name],"") | J79: =_xlfn.XLOOKUP(C79,Inventory_Data[HSN-Code],Inventory_Data[Unit/Cost],"") | K79: =IF(I79="","",I79*J79) | M79: =IF(L79="","",L79+_xlfn.XLOOKUP(C79,Vendor_Data[HSN Code.],Vendor_Data[Delivery Time(in days)])) | N79: =IF(M79="","",IF(M79<TODAY(),"Completed","Pending"))

Sheet Report Summary
L2: Reorder | M2: Yes
C4: Count of Product | E4: Sum of Total Value | H4: Sum of Quantity in Stock | L4: Count of Product
C5: 40 | E5: 12207000 | H5: 518 | L5: 16
C7: Sum of Quantity in Stock | D7: Site Location | H7: Product Description | I7: Inventory Value | L7: Reorder Value | M7: Yes | O7: Product Name | P7: Total Quantity | Q7: Reorder
C8: Product Description | D8: WH-0041 | E8: WH-0042 | F8: Grand Total | H8: MacBook Air M2 13 | I8: 1250000 | O8: HP Envy x360 | P8: 15 | Q8: 10
C9: Laptop | D9: 67 | E9: 82 | F9: 149 | H9: iPhone 13 | I9: 700000 | L9: HSN-Code | M9: Low Qty. Stock | O9: HP Pavilion 15 | P9: 20 | Q9: 12
C10: Asus Zenbook 14 | E10: 12 | F10: 12 | H10: iPhone 15 Pro Max | I10: 525000 | L10: ASW-038 | M10: 1 | O10: HP spectre x360 | P10: 15 | Q10: 10
C11: Dell Alienware | D11: 12 | F11: 12 | H11: MacBook Pro M3 Max 16 | I11: 520000 | L11: ASW-040 | M11: 2 | O11: HP Victre 14s | P11: 15 | Q11: 10
C12: Dell Aspire | D12: 12 | F12: 12 | H12: iPad Pro 12 | I12: 510000 | L12: ASW-036 | M12: 3 | O12: iPad Mini | P12: 15 | Q12: 11
C13: HP Victer 14s | E13: 10 | F13: 10 | H13: iPhone 15 | I13: 480000 | L13: ASW-018 | M13: 4 | O13: iPad Pro 12 | P13: 17 | Q13: 12
C14: HP Envy x360 | D14: 15 | F14: 15 | H14: Sony Xperia 1V | I14: 450000 | L14: ASW-001 | M14: 6 | O14: iPhone 13 | P14: 20 | Q14: 12
C15: HP Pavilion 15 | E15: 20 | F15: 20 | H15: Sony Bravia 4k Led TV | I15: 380000 | L15: ASW-029 | M15: 7 | O15: iPhone 15 Pro Max | P15: 15 | Q15: 12
C16: HP spectre x360 | D16: 15 | F16: 15 | H16: One Plus Led TV | I16: 378000 | L16: ASW-005 | M16: 9 | O16: MacBook Air M2 13 | P16: 25 | Q16: 12
C17: HP Victre 14s | E17: 15 | F17: 15 | H17: Samsung Android TV | I17: 375000 | L17: ASW-012 | M17: 10 | O17: Motorola Edge 40 | P17: 18 | Q17: 11
C18: MacBook Air M2 13 | E18: 25 | F18: 25 | H18: Grand Total | I18: 5568000 | L18: ASW-035 | M18: 10 | O18: Nothing Phone | P18: 20 | Q18: 11
C19: MacBook Pro M3 Max 16 | D19: 13 | F19: 13 | L19: ASW-037 | M19: 10 | O19: One Plus Led TV | P19: 18 | Q19: 12
C20: Led TV | D20: 55 | E20: 37 | F20: 92 | L20: ASW-006 | M20: 10 | O20: One Plus Ultra | P20: 15 | Q20: 12
C21: Google Smart TV | D21: 10 | F21: 10 | L21: ASW-028 | M21: 10 | O21: Samsung Android TV | P21: 15 | Q21: 11
C22: One Plus Led TV | E22: 18 | F22: 18 | L22: ASW-031 | M22: 12 | O22: Samsung Galaxy A49+ | P22: 15 | Q22: 11
C23: Samsung Android TV | D23: 15 | F23: 15 | L23: ASW-015 | M23: 12 | O23: Samsung Galaxy S23 FE | P23: 15 | Q23: 11
C24: Samsung Smart Led TV | D24: 14 | F24: 14 | L24: ASW-017 | M24: 12 | O24: Sony Bravia 4k Led TV | P24: 19 | Q24: 12
C25: Sony Bravia 4k Led TV | E25: 19 | F25: 19 | L25: ASW-002 | M25: 12 | O25: Sony Xperia 1V | P25: 15 | Q25: 10
C26: Sony Bravia Smart 4K | D26: 10 | F26: 10
C27: Xiaomi Android TV | D27: 6 | F27: 6
C28: Mobile Phone | D28: 82 | E28: 136 | F28: 218
C29: Google Pixel 7a | E29: 10 | F29: 10
C30: Google Pixel 8 Pro | E30: 14 | F30: 14
C31: iPad 16 | E31: 1 | F31: 1
C32: iPad 16 Pro Max | E32: 2 | F32: 2
C33: iPhone 13 | E33: 20 | F33: 20
C34: iPhone 15 | D34: 12 | F34: 12
C35: iPhone 15 Pro Max | D35: 15 | F35: 15
C36: Motorola Edge 40 | E36: 18 | F36: 18
C37: Nothing Phone | E37: 20 | F37: 20
C38: One Plus 12 | E38: 9 | F38: 9
C39: One Plus Ultra | D39: 15 | F39: 15
C40: Samsung F23 Plus | E40: 3 | F40: 3
C41: Samsung Galaxy A49+ | D41: 15 | F41: 15
C42: Samsung Galaxy S23 FE | D42: 15 | F42: 15
C43: Samsung Galaxy S24 Ultra | E43: 4 | F43: 4
...
